Workbook

Sheet Cover
B2: BANK OF GHANA - MICROFINANCE INSTITUTION
B3: Financial statements template: balance sheet, income statement and cash flow statement
B4: Prepared for a Ghanaian microfinance institution reporting under IFRS and the Bank of Ghana prudential framework
B6: WHAT IS IN THIS WORKBOOK
B7: Setup | C7: Institution name, licence tier, reporting periods and share count. Fill this in first - every other sheet takes its headings from here.
B8: Balance Sheet | C8: Statement of financial position, current and prior period, with a built-in balance check.
B9: Income Statement | C9: Statement of comprehensive income, down to total comprehensive income, with the appropriation lines below it.
B10: Cash Flow Statement | C10: Indirect method. The current-period column is built from the other two statements; only the prior-period column and the investing and financing lines are keyed in.
B11: Changes in Equity | C11: Movement in stated capital, statutory reserve, credit risk reserve and income surplus, with a check back to the balance sheet.
B12: Loan Classification | C12: Portfolio split by days past due, minimum provision by class, and the credit risk reserve computation.
B13: Prudential Ratios | C13: Capital base, capital adequacy, liquidity, single obligor, asset quality and performance ratios.
B14: Worked Example | C14: A fictitious but fully articulating set of figures showing the expected format and sign convention.
B16: HOW TO USE IT
B17: 1. | C17: Complete the Setup sheet. The institution name and both period dates flow into the heading of every statement.
B18: 2. | C18: Key the balance sheet and the income statement. Only the shaded cells take an entry; every subtotal is a formula.
B19: 3. | C19: Complete the loan classification sheet. The gross loans total there must equal the gross loans line on the balance sheet.
B20: 4. | C20: Complete the investing and financing sections of the cash flow statement and the prior-period column. The operating section builds itself.
B21: 5. | C21: Complete the changes in equity sheet and the yellow regulatory thresholds on the prudential ratios sheet.
B22: 6. | C22: Work through every check cell until each one reads OK before the return leaves the building.
B24: COLOUR AND SIGN CONVENTION
B25: Blue figures on a cream fill | C25: A cell you enter. Nothing else in the workbook should be typed over.
B26: Blue figures on a yellow fill | C26: A regulatory threshold or a key assumption. Confirm it against the Bank of Ghana notice in force before you rely on it.
B27: Black figures | C27: A formula. Do not overwrite.
B28: Green figures | C28: A link to another sheet in this workbook.
B29: Green fill | C29: A check cell. It reads OK or names the difference.
B30: Negative numbers | C30: All expenses, the impairment charge, the tax charge, dividends and the impairment allowance are entered as negative numbers. Subtotals add the column, so a positive expense will overstate profit.
B32: CHECKS BUILT IN
B33: Balance Sheet | C33: Total assets less total liabilities and shareholders' funds.
B34: Cash Flow Statement | C34: Closing cash per the cash flow statement against the cash line on the balance sheet.
B35: Changes in Equity | C35: Closing equity against total shareholders' funds on the balance sheet, both periods.
B36: Loan Classification | C36: Total gross loans by classification against the gross loans line on the balance sheet.
B37: Prudential Ratios | C37: Paid-up capital against the minimum, and the largest single exposure against the single obligor limit.
B39: BASIS, SOURCES AND WHAT THIS TEMPLATE DOES NOT DO
B40: Basis | C40: The line items follow IFRS as applied by Ghanaian deposit-taking institutions, together with the Ghana-specific items a Bank of Ghana return expects: susu deposits, the statutory reserve fund, the credit risk (regulatory) reserve, and loan classification by days past due.
B41: Not an official BoG form | C41: This is a working template built to the structure of a Bank of Ghana prudential return. It is not a scan or a reproduction of an official Bank of Ghana form, and it does not replace the return templates the Bank issues to licensed institutions.
B42: Regulatory figures | C42: No minimum paid-up capital, capital adequacy ratio, reserve requirement or single obligor limit is asserted as fact anywhere in this workbook. Every such figure sits in a yellow cell for you to enter from the notice in force. The provision rates on the loan classification sheet are pre-filled with the rates commonly applied to microfinance institutions and are likewise yellow: confirm them.
B43: Why | C43: The Bank of Ghana website (bog.gov.gh) could not be reached from the environment this workbook was built in, so the current thresholds could not be read off the source documents.
B44: Documents to check | C44: Operating Rules and Guidelines for Microfinance Institutions (Notice BG/GOV/SEC/2011/04, as amended); Notice No. 3/BOG/SEC/GOV/2026 on the revised microfinance sector framework; Banks and Specialised Deposit-Taking Institutions Act, 2016 (Act 930); Non-Bank Financial Institutions Act, 2008 (Act 774).
B45: Statutory reserve | C45: Section 34 of Act 930 sets the transfer to the statutory reserve fund as a proportion of net profit that varies with the ratio of existing reserves to paid-up capital. The template leaves the transfer as an entry rather than computing it.
B47: PREPARED
...

Sheet Setup
B2: REPORTING ENTITY AND PERIOD
B3: Complete this sheet first. Every other sheet reads its headings from here.
B5: Field | C5: Entry | D5: Guidance
B6: Name of the microfinance institution | C6: Akwaaba Microfinance Company Limited | D6: As registered with the Registrar of Companies.
B7: Bank of Ghana licence category / tier | C7: Tier 2 - Deposit-taking Microfinance Company | D7: Tier 1 / Tier 2 (MFC) / Tier 3 (Money Lender, Financial NGO) - or the category under the current BoG microfinance framework.
B8: Bank of Ghana licence number | D8: As shown on the licence certificate.
B9: Reporting currency | C9: Ghana Cedis (GH¢) | D9: BoG returns are rendered in Ghana Cedis.
B10: Current reporting period ended | C10: 31 December 2025 | D10: Column D heading on every statement.
B11: Prior reporting period ended | C11: 31 December 2024 | D11: Column E heading on every statement.
B12: Reporting frequency of this return | C12: Annual | D12: Monthly / Quarterly / Annual.
B13: Basis of preparation | C13: IFRS as adopted in Ghana, and the Bank of Ghana prudential requirements
B14: Ordinary shares in issue (number) | C14: 2000000 | D14: Used for the earnings per share line only.
B15: Prepared by (name and date) | D15: Sign-off required before submission.
B16: Reviewed / approved by (name and date) | D16: Ordinarily the Managing Director and the Board.

Sheet Balance Sheet
B1: =Setup!$C$6 -> Akwaaba Microfinance Company Limited
B2: STATEMENT OF FINANCIAL POSITION (BALANCE SHEET)
B3: ="As at "&Setup!$C$10 -> As at 31 December 2025
B4: All amounts are in Ghana Cedis (GH¢) unless otherwise stated
C6: Note | D6: ="Current period"&CHAR(10)&Setup!$C$10&CHAR(10)&"GH¢" -> Current period 31 December 2025 GH¢ | E6: ="Prior period"&CHAR(10)&Setup!$C$11&CHAR(10)&"GH¢" -> Prior period 31 December 2024 GH¢ | F6: Movement GH¢
B7: ASSETS
B8: Cash and cash equivalents
B9: Cash on hand | F9: =D9-E9 -> 0
B10: Balances with banks in Ghana | F10: =D10-E10 -> 0
B11: Balances with banks outside Ghana | F11: =D11-E11 -> 0
B12: Placements with banks and other financial institutions (maturing within 3 months) | F12: =D12-E12 -> 0
B13: Total cash and cash equivalents | D13: =SUM(D9:D12) -> 0 | E13: =SUM(E9:E12) -> 0 | F13: =D13-E13 -> 0
B15: Investments
B16: Government of Ghana treasury bills and bonds | F16: =D16-E16 -> 0
B17: Placements and deposits maturing after 3 months | F17: =D17-E17 -> 0
B18: Other investment securities | F18: =D18-E18 -> 0
B19: Total investments | D19: =SUM(D16:D18) -> 0 | E19: =SUM(E16:E18) -> 0 | F19: =D19-E19 -> 0
B21: Loans and advances to customers
B22: Gross loans and advances to customers | F22: =D22-E22 -> 0
B23: Less: allowance for impairment / expected credit losses (enter as negative) | F23: =D23-E23 -> 0
B24: Net loans and advances to customers | D24: =D22+D23 -> 0 | E24: =E22+E23 -> 0 | F24: =D24-E24 -> 0
B26: Other assets, prepayments and receivables | F26: =D26-E26 -> 0
B27: Current income tax asset | F27: =D27-E27 -> 0
B28: Investments in subsidiaries and associates | F28: =D28-E28 -> 0
B29: Property, plant and equipment | F29: =D29-E29 -> 0
B30: Right-of-use assets | F30: =D30-E30 -> 0
B31: Intangible assets | F31: =D31-E31 -> 0
B32: Deferred income tax asset | F32: =D32-E32 -> 0
B33: TOTAL ASSETS | D33: =D13+D19+D24+SUM(D26:D32) -> 0 | E33: =E13+E19+E24+SUM(E26:E32) -> 0 | F33: =D33-E33 -> 0
B35: LIABILITIES
B36: Deposits from customers
B37: Savings deposits | F37: =D37-E37 -> 0
B38: Susu deposits | F38: =D38-E38 -> 0
B39: Time and fixed deposits | F39: =D39-E39 -> 0
B40: Other customer deposit accounts | F40: =D40-E40 -> 0
B41: Total deposits from customers | D41: =SUM(D37:D40) -> 0 | E41: =SUM(E37:E40) -> 0 | F41: =D41-E41 -> 0
B43: Borrowings
B44: Due to banks and other financial institutions | F44: =D44-E44 -> 0
B45: Term borrowings and on-lending / wholesale funds | F45: =D45-E45 -> 0
B46: Total borrowings | D46: =SUM(D44:D45) -> 0 | E46: =SUM(E44:E45) -> 0 | F46: =D46-E46 -> 0
...

Sheet Income Statement
B1: =Setup!$C$6 -> Akwaaba Microfinance Company Limited
B2: STATEMENT OF COMPREHENSIVE INCOME (INCOME STATEMENT)
B3: ="For the period ended "&Setup!$C$10 -> For the period ended 31 December 2025
B4: All amounts are in Ghana Cedis (GH¢) unless otherwise stated
C6: Note | D6: ="Current period"&CHAR(10)&Setup!$C$10&CHAR(10)&"GH¢" -> Current period 31 December 2025 GH¢ | E6: ="Prior period"&CHAR(10)&Setup!$C$11&CHAR(10)&"GH¢" -> Prior period 31 December 2024 GH¢ | F6: Movement GH¢
B7: INTEREST INCOME AND EXPENSE
B8: Interest income on loans and advances to customers | F8: =D8-E8 -> 0
B9: Interest income on investments in government securities | F9: =D9-E9 -> 0
B10: Interest income on placements with financial institutions | F10: =D10-E10 -> 0
B11: Total interest income | D11: =SUM(D8:D10) -> 0 | E11: =SUM(E8:E10) -> 0 | F11: =D11-E11 -> 0
B12: Interest expense on customer deposits (enter as negative) | F12: =D12-E12 -> 0
B13: Interest expense on borrowings and leases (enter as negative) | F13: =D13-E13 -> 0
B14: Total interest expense | D14: =SUM(D12:D13) -> 0 | E14: =SUM(E12:E13) -> 0 | F14: =D14-E14 -> 0
B15: NET INTEREST INCOME | D15: =D11+D14 -> 0 | E15: =E11+E14 -> 0 | F15: =D15-E15 -> 0
B17: NON-INTEREST INCOME
B18: Fees and commission income | F18: =D18-E18 -> 0
B19: Fees and commission expense (enter as negative) | F19: =D19-E19 -> 0
B20: Net fees and commission income | D20: =D18+D19 -> 0 | E20: =E18+E19 -> 0 | F20: =D20-E20 -> 0
B21: Net trading and foreign exchange income | F21: =D21-E21 -> 0
B22: Other operating income (recoveries, sundry income) | F22: =D22-E22 -> 0
B23: TOTAL OPERATING INCOME | D23: =D15+D20+D21+D22 -> 0 | E23: =E15+E20+E21+E22 -> 0 | F23: =D23-E23 -> 0
B25: IMPAIRMENT AND OPERATING EXPENSES
B26: Impairment loss on loans and advances, net of recoveries (enter as negative) | F26: =D26-E26 -> 0
B27: Impairment loss on other financial assets (enter as negative) | F27: =D27-E27 -> 0
B28: NET OPERATING INCOME | D28: =D23+D26+D27 -> 0 | E28: =E23+E26+E27 -> 0 | F28: =D28-E28 -> 0
B30: Personnel expenses (enter as negative) | F30: =D30-E30 -> 0
B31: Depreciation of property, plant and equipment (enter as negative) | F31: =D31-E31 -> 0
B32: Depreciation of right-of-use assets (enter as negative) | F32: =D32-E32 -> 0
B33: Amortisation of intangible assets (enter as negative) | F33: =D33-E33 -> 0
B34: Directors' emoluments (enter as negative) | F34: =D34-E34 -> 0
B35: Occupancy, utilities and general administrative expenses (enter as negative) | F35: =D35-E35 -> 0
B36: Other operating expenses (enter as negative) | F36: =D36-E36 -> 0
B37: TOTAL OPERATING EXPENSES | D37: =SUM(D30:D36) -> 0 | E37: =SUM(E30:E36) -> 0 | F37: =D37-E37 -> 0
B38: PROFIT / (LOSS) BEFORE TAX | D38: =D28+D37 -> 0 | E38: =E28+E37 -> 0 | F38: =D38-E38 -> 0
B40: TAXATION AND RESULT FOR THE PERIOD
B41: Current income tax expense (enter as negative) | F41: =D41-E41 -> 0
B42: Deferred income tax (charge) / credit | F42: =D42-E42 -> 0
B43: Growth and Sustainability Levy, where applicable (enter as negative) | F43: =D43-E43 -> 0
B44: PROFIT / (LOSS) AFTER TAX | D44: =D38+D41+D42+D43 -> 0 | E44: =E38+E41+E42+E43 -> 0 | F44: =D44-E44 -> 0
B46: Gain on revaluation of property, net of tax | F46: =D46-E46 -> 0
...

Sheet Cash Flow Statement
B1: =Setup!$C$6 -> Akwaaba Microfinance Company Limited
B2: STATEMENT OF CASH FLOWS (INDIRECT METHOD)
B3: ="For the period ended "&Setup!$C$10 -> For the period ended 31 December 2025
B4: All amounts are in Ghana Cedis (GH¢) unless otherwise stated
C6: Note | D6: ="Current period"&CHAR(10)&Setup!$C$10&CHAR(10)&"GH¢" -> Current period 31 December 2025 GH¢ | E6: ="Prior period"&CHAR(10)&Setup!$C$11&CHAR(10)&"GH¢" -> Prior period 31 December 2024 GH¢
B7: CASH FLOWS FROM OPERATING ACTIVITIES
B8: Profit / (loss) before tax | D8: ='Income Statement'!D38 -> 0
B9: Adjustments for non-cash and non-operating items:
B10: Depreciation of property, plant and equipment | D10: =-'Income Statement'!D31 -> 0
B11: Depreciation of right-of-use assets | D11: =-'Income Statement'!D32 -> 0
B12: Amortisation of intangible assets | D12: =-'Income Statement'!D33 -> 0
B13: Impairment loss on loans and advances | D13: =-'Income Statement'!D26 -> 0
B14: Impairment loss on other financial assets | D14: =-'Income Statement'!D27 -> 0
B15: Interest expense on borrowings and leases | D15: =-'Income Statement'!D13 -> 0
B16: (Profit) / loss on disposal of property, plant and equipment
B17: Other non-cash items
B18: Operating profit before changes in operating assets and liabilities | D18: =SUM(D8:D17) -> 0 | E18: =SUM(E8:E17) -> 0 | F18: =D18-E18 -> 0
B20: Changes in operating assets and liabilities:
B21: (Increase) / decrease in gross loans and advances to customers | D21: =-('Balance Sheet'!D22-'Balance Sheet'!E22) -> 0
B22: (Increase) / decrease in other assets, prepayments and receivables | D22: =-('Balance Sheet'!D26-'Balance Sheet'!E26) -> 0
B23: (Increase) / decrease in restricted and mandatory reserve balances
B24: Increase / (decrease) in deposits from customers | D24: ='Balance Sheet'!D41-'Balance Sheet'!E41 -> 0
B25: Increase / (decrease) in other liabilities, accruals and provisions | D25: ='Balance Sheet'!D49-'Balance Sheet'!E49 -> 0
B26: Cash generated from / (used in) operations | D26: =D18+SUM(D21:D25) -> 0 | E26: =E18+SUM(E21:E25) -> 0 | F26: =D26-E26 -> 0
B27: Income tax paid (enter as negative)
B28: NET CASH FROM / (USED IN) OPERATING ACTIVITIES | D28: =D26+D27 -> 0 | E28: =E26+E27 -> 0 | F28: =D28-E28 -> 0
B30: CASH FLOWS FROM INVESTING ACTIVITIES
B31: Purchase of property, plant and equipment (enter as negative)
B32: Proceeds from disposal of property, plant and equipment
B33: Purchase of intangible assets (enter as negative)
B34: Purchase of investment securities (enter as negative)
B35: Proceeds from maturity and disposal of investment securities
B36: Dividends and other investment income received
B37: NET CASH FROM / (USED IN) INVESTING ACTIVITIES | D37: =SUM(D31:D36) -> 0 | E37: =SUM(E31:E36) -> 0 | F37: =D37-E37 -> 0
B39: CASH FLOWS FROM FINANCING ACTIVITIES
B40: Proceeds from the issue of shares / capital injection
B41: Proceeds from borrowings
B42: Repayment of borrowings (enter as negative)
B43: Interest paid on borrowings (enter as negative)
B44: Principal element of lease payments (enter as negative)
...

Sheet Changes in Equity
B1: =Setup!$C$6 -> Akwaaba Microfinance Company Limited
B2: STATEMENT OF CHANGES IN EQUITY
B3: ="For the period ended "&Setup!$C$10 -> For the period ended 31 December 2025
B4: All amounts are in Ghana Cedis (GH¢) unless otherwise stated
B7: ="Period ended "&Setup!$C$10 -> Period ended 31 December 2025
C8: Stated capital GH¢ | D8: Statutory reserve fund GH¢ | E8: Credit risk reserve GH¢ | F8: Revaluation reserve GH¢ | G8: Other reserves GH¢ | H8: Income surplus GH¢ | I8: Total GH¢
B9: Balance at the beginning of the period | I9: =SUM(C9:H9) -> 0
B10: Profit / (loss) for the period | I10: =SUM(C10:H10) -> 0
B11: Other comprehensive income for the period | I11: =SUM(C11:H11) -> 0
B12: Transfer to / (from) the statutory reserve fund | I12: =SUM(C12:H12) -> 0
B13: Transfer to / (from) the credit risk (regulatory) reserve | I13: =SUM(C13:H13) -> 0
B14: Issue of shares / capital injection | I14: =SUM(C14:H14) -> 0
B15: Dividends declared and paid | I15: =SUM(C15:H15) -> 0
B16: Other movements | I16: =SUM(C16:H16) -> 0
B17: Balance at the end of the period | C17: =SUM(C9:C16) -> 0 | D17: =SUM(D9:D16) -> 0 | E17: =SUM(E9:E16) -> 0 | F17: =SUM(F9:F16) -> 0 | G17: =SUM(G9:G16) -> 0 | H17: =SUM(H9:H16) -> 0 | I17: =SUM(I9:I16) -> 0
B20: ="Period ended "&Setup!$C$11 -> Period ended 31 December 2024
C21: Stated capital GH¢ | D21: Statutory reserve fund GH¢ | E21: Credit risk reserve GH¢ | F21: Revaluation reserve GH¢ | G21: Other reserves GH¢ | H21: Income surplus GH¢ | I21: Total GH¢
B22: Balance at the beginning of the period | I22: =SUM(C22:H22) -> 0
B23: Profit / (loss) for the period | I23: =SUM(C23:H23) -> 0
B24: Other comprehensive income for the period | I24: =SUM(C24:H24) -> 0
B25: Transfer to / (from) the statutory reserve fund | I25: =SUM(C25:H25) -> 0
B26: Transfer to / (from) the credit risk (regulatory) reserve | I26: =SUM(C26:H26) -> 0
B27: Issue of shares / capital injection | I27: =SUM(C27:H27) -> 0
B28: Dividends declared and paid | I28: =SUM(C28:H28) -> 0
B29: Other movements | I29: =SUM(C29:H29) -> 0
B30: Balance at the end of the period | C30: =SUM(C22:C29) -> 0 | D30: =SUM(D22:D29) -> 0 | E30: =SUM(E22:E29) -> 0 | F30: =SUM(F22:F29) -> 0 | G30: =SUM(G22:G29) -> 0 | H30: =SUM(H22:H29) -> 0 | I30: =SUM(I22:I29) -> 0
B32: Agreement check: closing equity above against the statement of financial position | C32: =IF(ROUND(I17-'Balance Sheet'!D62,0)=0,"CURRENT PERIOD: OK","CURRENT PERIOD OUT BY "&TEXT(I17-'Balance Sheet'!D62,"#,##0")) -> CURRENT PERIOD: OK | E32: =IF(ROUND(I30-'Balance Sheet'!E62,0)=0,"PRIOR PERIOD: OK","PRIOR PERIOD OUT BY "&TEXT(I30-'Balance Sheet'!E62,"#,##0")) -> PRIOR PERIOD: OK
B34: Enter reductions (dividends, transfers out of income surplus) as negative numbers. A transfer between reserves must net to nil across the row.

Sheet Loan Classification
B1: =Setup!$C$6 -> Akwaaba Microfinance Company Limited
B2: LOAN PORTFOLIO CLASSIFICATION AND PROVISIONING
B3: ="As at "&Setup!$C$10 -> As at 31 December 2025
B4: All amounts are in Ghana Cedis (GH¢) unless otherwise stated
B6: Classification | C6: Days past due | D6: Gross loan balance GH¢ | E6: % of portfolio | F6: Minimum provision rate | G6: Minimum provision required GH¢ | H6: Security / collateral value GH¢ | I6: Notes
B7: Current | C7: 0 - 30 days | E7: =IFERROR(D7/$D$12,"") | F7: 0.01 | G7: =D7*F7 -> 0 | I7: The days-past-due bands and provision rates in the yellow cells are the ones commonly applied to microfinance institutions. Confirm them against the Bank of Ghana notice in force for your tier before you file, and overwrite these cells if they differ.
B8: Other Loans Especially Mentioned (OLEM) | C8: 31 - 60 days | E8: =IFERROR(D8/$D$12,"") | F8: 0.1 | G8: =D8*F8 -> 0
B9: Substandard | C9: 61 - 90 days | E9: =IFERROR(D9/$D$12,"") | F9: 0.25 | G9: =D9*F9 -> 0
B10: Doubtful | C10: 91 - 180 days | E10: =IFERROR(D10/$D$12,"") | F10: 0.5 | G10: =D10*F10 -> 0
B11: Loss | C11: Over 180 days | E11: =IFERROR(D11/$D$12,"") | F11: 1 | G11: =D11*F11 -> 0
B12: TOTAL GROSS LOANS AND ADVANCES | D12: =SUM(D7:D11) -> 0 | E12: =IFERROR(D12/D12,"") | G12: =SUM(G7:G11) -> 0 | H12: =SUM(H7:H11) -> 0
B14: RECONCILIATION TO THE IMPAIRMENT ALLOWANCE AND THE CREDIT RISK RESERVE
B15: Bank of Ghana minimum provision required | D15: =G12 -> 0
B16: IFRS 9 expected credit loss allowance carried in the balance sheet | D16: =-'Balance Sheet'!D23 -> 0
B17: Credit risk (regulatory) reserve required | D17: =MAX(0,D15-D16) -> 0
B18: Credit risk (regulatory) reserve currently held in equity | D18: ='Balance Sheet'!D59 -> 0
B19: Further transfer to / (release from) the credit risk reserve | D19: =D17-D18 -> 0
B21: PORTFOLIO QUALITY
B22: Portfolio at risk over 30 days (PAR>30) | D22: =IFERROR((D12-D7)/D12,"")
B23: Non-performing loan ratio (substandard, doubtful and loss) | D23: =IFERROR(SUM(D9:D11)/D12,"")
B24: Provision coverage of non-performing loans | D24: =IFERROR(-'Balance Sheet'!D23/SUM(D9:D11),"")
B25: Gross loans as a percentage of total assets | D25: =IFERROR('Balance Sheet'!D22/'Balance Sheet'!D33,"")
B27: Check: total gross loans above must equal the gross loans line on the balance sheet. | D27: =IF(ROUND(D12-'Balance Sheet'!D22,0)=0,"OK","OUT BY "&TEXT(D12-'Balance Sheet'!D22,"#,##0")) -> OK

Sheet Prudential Ratios
B1: =Setup!$C$6 -> Akwaaba Microfinance Company Limited
B2: PRUDENTIAL RATIOS AND PERFORMANCE INDICATORS
B3: ="As at / for the period ended "&Setup!$C$10 -> As at / for the period ended 31 December 2025
B4: All amounts are in Ghana Cedis (GH¢) unless otherwise stated
B6: Indicator | C6: Current period | D6: Prior period | E6: Regulatory minimum / limit | F6: Status | G6: Basis of computation
B7: A. CAPITAL
B8: Stated capital (paid-up capital) | C8: ='Balance Sheet'!D56 -> 0 | D8: ='Balance Sheet'!E56 -> 0 | G8: Balance sheet.
B9: Disclosed reserves (income surplus, statutory and other reserves) | C9: ='Balance Sheet'!D62-'Balance Sheet'!D56 -> 0 | D9: ='Balance Sheet'!E62-'Balance Sheet'!E56 -> 0 | G9: Total shareholders' funds less stated capital.
B10: Less: intangible assets | C10: =-'Balance Sheet'!D31 -> 0 | D10: =-'Balance Sheet'!E31 -> 0 | G10: Intangibles are deducted from the capital base.
B11: Less: deferred tax asset | C11: =-'Balance Sheet'!D32 -> 0 | D11: =-'Balance Sheet'!E32 -> 0 | G11: Deduct where the supervisor does not recognise it as capital.
B12: Less: other regulatory deductions (enter as negative) | G12: Unsecured connected-party exposures and any other deduction the Bank of Ghana directs.
B13: ADJUSTED CAPITAL BASE (NET OWN FUNDS) | C13: =SUM(C8:C12) -> 0 | D13: =SUM(D8:D12) -> 0
B14: Minimum paid-up capital required by the Bank of Ghana | G14: Enter the figure applicable to your tier under the microfinance framework currently in force. VERIFY - this is not pre-filled.
B15: Paid-up capital compliance | C15: =IF(N(C14)=0,"",IF(C8>=C14,"Compliant","SHORTFALL OF "&TEXT(C14-C8,"#,##0")))
B17: B. CAPITAL ADEQUACY
B18: Total risk-weighted assets | G18: Computed on the Bank of Ghana capital adequacy return. Enter the total here.
B19: Capital adequacy ratio | C19: =IFERROR(C13/C18,"") | D19: =IFERROR(D13/D18,"") | F19: =IF(OR(N(C19)=0,N(E19)=0),"",IF(C19>=E19,"Compliant","BREACH")) | G19: Adjusted capital base divided by total risk-weighted assets. Confirm the minimum in the yellow cell against the notice in force.
B20: Leverage: shareholders' funds to total assets | C20: =IFERROR('Balance Sheet'!D62/'Balance Sheet'!D33,"") | D20: =IFERROR('Balance Sheet'!E62/'Balance Sheet'!E33,"") | G20: Total shareholders' funds divided by total assets.
B22: C. LIQUIDITY AND RESERVES
B23: Liquid assets | C23: ='Balance Sheet'!D13+'Balance Sheet'!D16 -> 0 | D23: ='Balance Sheet'!E13+'Balance Sheet'!E16 -> 0 | G23: Cash and cash equivalents plus Government of Ghana securities.
B24: Total deposits from customers | C24: ='Balance Sheet'!D41 -> 0 | D24: ='Balance Sheet'!E41 -> 0 | G24: Balance sheet.
B25: Liquidity ratio | C25: =IFERROR(C23/C24,"") | D25: =IFERROR(D23/D24,"") | F25: =IF(OR(N(C25)=0,N(E25)=0),"",IF(C25>=E25,"Compliant","BREACH")) | G25: Liquid assets divided by total deposits. Overwrite the yellow cell with the primary reserve requirement applicable to your tier.
B26: Primary reserve requirement (% of total deposits) | G26: VERIFY against the current Bank of Ghana notice.
B27: Primary reserve amount required | C27: =C24*C26 -> 0 | D27: =D24*D26 -> 0 | G27: Total deposits multiplied by the rate above.
B29: D. CREDIT CONCENTRATION
B30: Single obligor limit (% of net own funds) | G30: VERIFY against the current Bank of Ghana notice for your tier.
B31: Maximum permitted exposure to a single borrower or group | C31: =C13*C30 -> 0 | D31: =D13*D30 -> 0 | G31: Adjusted capital base multiplied by the limit above.
B32: Largest single exposure actually outstanding | G32: From the loan ledger, aggregated for connected borrowers.
B33: Single obligor compliance | C33: =IF(N(C31)=0,"",IF(C32<=C31,"Compliant","EXCESS OF "&TEXT(C32-C31,"#,##0")))
B34: Deposit concentration ceiling (% of paid-up capital) | G34: The 2011 operating rules cap any single deposit at 5% of paid-up capital for Tier 2. VERIFY against the framework in force.
B35: Maximum permitted single deposit | C35: =C8*C34 -> 0 | D35: =D8*D34 -> 0 | G35: Paid-up capital multiplied by the ceiling above.
B36: Largest single deposit held | G36: From the deposit ledger.
B38: E. ASSET QUALITY
B39: Portfolio at risk over 30 days (PAR>30) | C39: =IFERROR('Loan Classification'!D22,"") | G39: From the loan classification sheet.
B41: F. PROFITABILITY AND EFFICIENCY
B42: Return on average assets | C42: =IFERROR('Income Statement'!D44/AVERAGE('Balance Sheet'!D33,'Balance Sheet'!E33),"") | G42: Profit after tax divided by the average of opening and closing total assets.
B43: Return on average shareholders' funds | C43: =IFERROR('Income Statement'!D44/AVERAGE('Balance Sheet'!D62,'Balance Sheet'!E62),"") | G43: Profit after tax divided by average shareholders' funds.
B44: Gross portfolio yield | C44: =IFERROR('Income Statement'!D8/AVERAGE('Balance Sheet'!D22,'Balance Sheet'!E22),"") | G44: Interest income on loans divided by average gross loans.
B45: Cost to income ratio | C45: =IFERROR(-'Income Statement'!D37/'Income Statement'!D23,"") | G45: Total operating expenses divided by total operating income.
B46: Operating expense ratio | C46: =IFERROR(-'Income Statement'!D37/AVERAGE('Balance Sheet'!D22,'Balance Sheet'!E22),"") | G46: Total operating expenses divided by average gross loans.
...

Sheet Worked Example
B1: WORKED EXAMPLE - Akwaaba Microfinance Company Limited (fictitious)
B2: An illustrative, fully articulating set of figures showing the expected format and sign convention. The three statements tie to each other: the balance sheet balances, the cash flow statement reconciles to the cash line, and the credit risk reserve equals the excess of the Bank of Ghana minimum provision over the IFRS 9 allowance.
B6: STATEMENT OF FINANCIAL POSITION AS AT 31 DECEMBER 2025 (GH¢)
C7: 2025 | D7: 2024
B8: Cash on hand | C8: 200000 | D8: 150000
B9: Balances with banks | C9: 1600000 | D9: 1100000
B10: Placements maturing within 3 months | C10: 1000000 | D10: 600000
B11: Total cash and cash equivalents | C11: =SUM(C8:C10) -> 2800000 | D11: =SUM(D8:D10) -> 1850000
B12: Government of Ghana treasury bills and bonds | C12: 1800000 | D12: 1500000
B13: Gross loans and advances to customers | C13: 9600000 | D13: 7900000
B14: Less: allowance for impairment (IFRS 9) | C14: -990000 | D14: -560000
B15: Net loans and advances to customers | C15: =C13+C14 -> 8610000 | D15: =D13+D14 -> 7340000
B16: Other assets and prepayments | C16: 340000 | D16: 290000
B17: Property, plant and equipment | C17: 1250000 | D17: 1120000
B18: Right-of-use assets | C18: 210000 | D18: 260000
B19: Intangible assets | C19: 90000 | D19: 70000
B20: Deferred income tax asset | C20: 120000 | D20: 100000
B21: TOTAL ASSETS | C21: =C11+C12+C15+SUM(C16:C20) -> 15220000 | D21: =D11+D12+D15+SUM(D16:D20) -> 12530000
B23: Savings deposits | C23: 4200000 | D23: 3500000
B24: Susu deposits | C24: 1650000 | D24: 1300000
B25: Time and fixed deposits | C25: 3100000 | D25: 2600000
B26: Total deposits from customers | C26: =SUM(C23:C25) -> 8950000 | D26: =SUM(D23:D25) -> 7400000
B27: Borrowings | C27: 2000000 | D27: 1600000
B28: Lease liabilities | C28: 230000 | D28: 280000
B29: Other liabilities and accruals | C29: 610000 | D29: 470000
B30: Current income tax liability | C30: 180000 | D30: 105000
B31: TOTAL LIABILITIES | C31: =C26+SUM(C27:C30) -> 11970000 | D31: =D26+SUM(D27:D30) -> 9855000
B33: Stated capital | C33: 2000000 | D33: 2000000
B34: Statutory reserve fund | C34: 520000 | D34: 420000
B35: Credit risk (regulatory) reserve | C35: 79000 | D35: 120000
B36: Income surplus | C36: 651000 | D36: 135000
B37: TOTAL SHAREHOLDERS' FUNDS | C37: =SUM(C33:C36) -> 3250000 | D37: =SUM(D33:D36) -> 2675000
B38: TOTAL LIABILITIES AND SHAREHOLDERS' FUNDS | C38: =C31+C37 -> 15220000 | D38: =D31+D37 -> 12530000
B39: Balance check | C39: =IF(ROUND(C21-C38,0)=0,"OK","OUT BY "&TEXT(C21-C38,"#,##0")) -> OK | D39: =IF(ROUND(D21-D38,0)=0,"OK","OUT BY "&TEXT(D21-D38,"#,##0")) -> OK
B41: STATEMENT OF COMPREHENSIVE INCOME FOR THE YEAR ENDED 31 DECEMBER 2025 (GH¢)
C42: 2025 | D42: 2024
B43: Interest income on loans and advances | C43: 4250000 | D43: 3480000
B44: Interest income on investments | C44: 260000 | D44: 210000
B45: Total interest income | C45: =SUM(C43:C44) -> 4510000 | D45: =SUM(D43:D44) -> 3690000
B46: Interest expense on customer deposits | C46: -760000 | D46: -620000
...
